order-book/a1-a2-testcases/intermediate-random-1.in

    # Random single threaded test case
    
1
o
S 0 AAPL 5492 13
C 0
C 0
C 0
B 1 AMZN 5824 12
B 2 AAPL 2818 19
C 1
S 3 GOOG 5601 7
C 3
S 4 AMZN 2088 1
B 5 GOOG 1435 10
B 6 AAPL 3553 6
S 7 AAPL 8963 20
C 5
S 8 AMZN 2028 20
B 9 GOOG 4240 7
C 2
C 2
S 10 GOOG 8467 4
C 8
S 11 GOOG 3958 6
S 12 GOOG 1541 16
S 13 GOOG 2003 8
C 13
S 14 GOOG 1724 11
B 15 AMZN 3799 6
S 16 GOOG 3720 1
C 2
B 17 AMZN 4029 5
S 18 AMZN 5516 5
B 19 AMZN 8361 9
S 20 AAPL 2004 19
S 21 AAPL 1864 15
S 22 AAPL 1625 11
S 23 AAPL 5265 15
C 13
S 24 AAPL 1684 12
B 25 GOOG 2527 8
B 26 GOOG 4268 5
B 27 AMZN 4570 15
C 12
C 1
C 24
C 3
C 10
B 28 GOOG 3010 14
B 29 AAPL 6948 10
C 16
B 30 GOOG 6840 10
S 31 AMZN 2028 7
S 32 AAPL 4492 3
B 33 GOOG 8868 19
S 34 GOOG 7026 19
C 25
S 35 AAPL 4225 6
C 0
C 22
S 36 AMZN 5230 2
S 37 AMZN 5717 14
B 38 AAPL 3715 1
C 22
S 39 AAPL 1607 14
S 40 GOOG 5668 1
B 41 GOOG 1594 3
S 42 AMZN 4641 12
S 43 AAPL 5044 20
S 44 AMZN 6683 5
S 45 AMZN 6381 11
C 34
C 34
B 46 AMZN 8056 12
S 47 AMZN 8884 11
S 48 GOOG 8850 18
S 49 AMZN 4599 20
S 50 AAPL 4204 18
B 51 AAPL 5723 9
S 52 AMZN 5211 19
B 53 AMZN 2784 10
S 54 AAPL 4476 1
B 55 AAPL 2843 10
B 56 AMZN 3621 15
C 44
C 52
S 57 AMZN 8185 17
S 58 AMZN 5873 15
B 59 GOOG 7723 11
B 60 AAPL 7620 18
S 61 AAPL 8202 18
C 18
C 29
S 62 AAPL 7854 9
S 63 AAPL 4024 11
C 62
S 64 GOOG 8687 17
B 65 GOOG 7856 16
S 66 GOOG 7960 9
B 67 AMZN 5487 17
B 68 AAPL 7981 20
S 69 AMZN 3453 1
B 70 GOOG 3937 13
S 71 GOOG 5981 6
B 72 AAPL 1991 7
B 73 GOOG 5740 20
C 7
S 74 AMZN 1522 5
S 75 GOOG 3105 17
C 21
S 76 GOOG 8366 8
C 35
C 45
B 77 AAPL 7197 14
C 60
S 78 AMZN 4729 2
B 79 AMZN 2266 9
B 80 AAPL 7300 3
B 81 AAPL 4573 19
C 77
S 82 GOOG 7289 17
S 83 AAPL 3180 19
C 81
S 84 AAPL 7326 16
S 85 GOOG 3455 13
C 22
B 86 AMZN 6201 17
S 87 AMZN 8767 8
S 88 AMZN 7486 7
B 89 AMZN 2164 17
B 90 GOOG 5253 5
S 91 AAPL 6862 7
B 92 AMZN 5954 14
C 80
C 51
B 93 AMZN 5818 8
C 25
B 94 AMZN 6984 19
B 95 AAPL 4990 18
S 96 AAPL 1358 11
S 97 GOOG 7819 5
S 98 GOOG 2502 6
C 15
S 99 AAPL 1234 15
C 20
C 23
S 100 GOOG 4999 11
B 101 GOOG 4237 12
S 102 GOOG 7195 4
S 103 AAPL 8562 8
B 104 AAPL 5295 6
S 105 AMZN 3894 13
C 42
B 106 GOOG 2058 18
S 107 AMZN 5583 4
S 108 GOOG 5151 16
C 94
S 109 GOOG 7378 3
C 21
B 110 AMZN 3796 14
C 37
B 111 AMZN 6908 7
C 95
S 112 AMZN 5904 16
S 113 AAPL 4446 18
B 114 GOOG 5464 1
B 115 AAPL 2075 19
C 83
B 116 GOOG 2534 6
S 117 AAPL 2425 7
S 118 AAPL 2883 18
C 41
C 107
S 119 AAPL 3252 11
C 8
B 120 GOOG 8204 20
S 121 AMZN 6601 20
S 122 GOOG 5108 8
C 104
C 21
S 123 AAPL 5805 3
S 124 GOOG 4093 11
C 49
C 32
B 125 GOOG 3215 20
S 126 AMZN 4117 10
B 127 AAPL 5088 13
S 128 AAPL 6884 7
B 129 GOOG 8704 5
S 130 GOOG 5143 8
B 131 AAPL 6080 4
C 74
C 47
B 132 GOOG 6796 13
C 73
C 20
S 133 GOOG 2033 7
S 134 AAPL 4379 13
B 135 AMZN 5945 19
B 136 AAPL 5317 6
C 10
C 49
C 111
C 107
S 137 AMZN 5906 2
C 31
B 138 AMZN 5407 1
S 139 GOOG 5661 18
C 0
S 140 GOOG 7058 13
B 141 GOOG 3815 20
S 142 GOOG 5928 11
C 47
S 143 GOOG 1305 15
B 144 AMZN 6650 19
B 145 AMZN 7617 17
B 146 AMZN 7455 9
B 147 AMZN 8985 6
C 122
S 148 AMZN 3793 1
B 149 GOOG 5091 20
B 150 AAPL 3858 3
B 151 GOOG 8454 2
B 152 AMZN 1488 6
C 35
B 153 AMZN 4675 5
S 154 AMZN 2648 5
S 155 AAPL 2808 4
C 18
C 11
B 156 AAPL 3374 11
C 126
B 157 AMZN 1688 5
S 158 GOOG 5963 20
S 159 GOOG 3243 5
C 75
C 108
C 42
S 160 GOOG 4831 18
S 161 AMZN 2635 6
S 162 AAPL 6046 17
C 154
B 163 AMZN 3981 20
B 164 GOOG 1763 18
B 165 GOOG 1900 16
C 125
B 166 AAPL 2673 19
C 31
B 167 AAPL 1954 15
S 168 AMZN 4169 10
S 169 GOOG 1458 17
B 170 AAPL 6045 8
S 171 AMZN 3415 1
B 172 AMZN 5837 20
S 173 GOOG 2190 16
C 34
S 174 AAPL 2286 10
B 175 GOOG 2090 1
B 176 GOOG 8406 4
C 156
C 116
S 177 GOOG 5357 6
C 65
B 178 AMZN 3606 11
S 179 AMZN 3733 1
C 124
B 180 AAPL 3854 18
S 181 GOOG 7639 1
C 35
S 182 AAPL 7156 1
C 37
C 176
B 183 AMZN 5378 6
C 87
C 173
B 184 AMZN 6482 4
S 185 AMZN 2756 6
C 92
C 174
C 132
S 186 AMZN 8050 10
C 106
C 118
C 148
B 187 AMZN 7863 3
S 188 AAPL 7689 3
B 189 AMZN 5359 14
C 103
C 99
B 190 GOOG 8369 17
B 191 GOOG 4006 19
B 192 AAPL 3990 14
C 53
B 193 GOOG 6973 3
S 194 AAPL 6899 13
C 96
S 195 GOOG 6269 14
B 196 AMZN 1495 11
S 197 GOOG 1033 17
S 198 AAPL 7331 11
S 199 AMZN 7050 19
C 50
C 121
C 168
S 200 GOOG 1023 3
S 201 GOOG 3934 14
C 44
C 101
C 142
S 202 GOOG 1051 16
C 201
B 203 AMZN 6677 15
C 70
C 137
C 6
B 204 AMZN 8499 18
C 117
C 185
C 97
C 77
B 205 AMZN 4170 3
B 206 GOOG 6872 4
B 207 GOOG 4182 7
B 208 GOOG 7685 17
B 209 AAPL 6585 15
S 210 GOOG 4336 7
B 211 GOOG 8307 11
S 212 AMZN 6233 4
C 101
B 213 GOOG 4298 6
C 147
S 214 GOOG 6255 11
B 215 AAPL 1707 16
S 216 GOOG 1653 8
C 134
S 217 AAPL 3147 11
S 218 AAPL 1746 9
C 138
B 219 AAPL 1447 10
S 220 GOOG 2919 11
S 221 AAPL 6010 19
S 222 GOOG 4363 8
C 127
B 223 GOOG 4023 18
B 224 AMZN 5025 20
C 202
S 225 AMZN 8659 7
C 125
S 226 AAPL 1690 9
B 227 AMZN 5823 16
B 228 AAPL 2089 17
C 40
C 152
B 229 AAPL 5427 7
C 84
B 230 GOOG 7187 5
S 231 GOOG 8949 7
C 84
S 232 GOOG 7436 1
C 154
B 233 AAPL 5356 13
B 234 AMZN 6681 1
S 235 AMZN 8513 5
C 135
S 236 AMZN 4891 1
B 237 GOOG 1357 10
B 238 GOOG 5990 19
S 239 AMZN 6736 7
C 138
C 88
S 240 GOOG 1199 11
C 91
C 45
S 241 GOOG 7749 15
C 160
C 62
C 143
S 242 GOOG 2951 5
C 186
B 243 AMZN 6051 12
C 188
S 244 GOOG 3715 14
S 245 AAPL 5306 6
C 34
S 246 AAPL 8016 3
S 247 GOOG 3262 1
S 248 AMZN 6007 3
B 249 GOOG 2696 11
C 188
S 250 GOOG 1277 1
C 132
C 114
B 251 AAPL 8416 12
C 136
B 252 GOOG 7758 9
S 253 GOOG 2197 12
B 254 AMZN 4340 14
C 194
C 121
S 255 GOOG 6497 5
S 256 GOOG 5628 4
S 257 AMZN 7790 2
B 258 AMZN 5553 8
S 259 GOOG 4873 13
C 50
S 260 AMZN 7222 5
C 87
S 261 GOOG 5327 19
C 195
B 262 AMZN 5264 13
B 263 GOOG 3900 3
C 139
C 46
S 264 GOOG 5118 1
B 265 AMZN 3664 6
B 266 AMZN 5578 7
S 267 AAPL 8814 12
B 268 AAPL 6000 13
B 269 AAPL 7566 2
S 270 GOOG 8132 9
C 203
B 271 AMZN 8406 12
B 272 AMZN 7274 13
B 273 GOOG 1405 20
B 274 AAPL 1055 8
B 275 AMZN 4873 4
B 276 GOOG 8186 13
S 277 AMZN 2725 2
C 145
B 278 AAPL 6185 3
B 279 GOOG 7119 11
S 280 AMZN 8821 14
B 281 GOOG 6707 16
B 282 AMZN 4101 4
S 283 GOOG 6771 18
B 284 GOOG 5278 15
C 27
B 285 GOOG 5149 17
B 286 GOOG 1870 7
S 287 GOOG 5446 7
C 227
C 152
B 288 AMZN 5482 15
S 289 AAPL 4801 15
B 290 GOOG 3997 4
B 291 GOOG 2267 13
S 292 GOOG 5387 13
S 293 GOOG 4377 1
S 294 AAPL 2115 14
B 295 GOOG 3130 20
B 296 AMZN 5974 16
S 297 GOOG 4705 9
C 130
C 182
C 0
C 148
S 298 AAPL 1059 16
B 299 GOOG 6388 16
S 300 AMZN 6024 9
C 62
B 301 AAPL 7294 8
C 13
B 302 AAPL 4037 1
B 303 AAPL 8551 1
B 304 AAPL 3899 10
S 305 GOOG 1910 2
B 306 GOOG 3241 19
B 307 GOOG 5236 18
S 308 GOOG 8551 2
C 228
S 309 AMZN 6831 13
B 310 AAPL 4215 14
S 311 GOOG 1195 3
C 231
S 312 AMZN 7233 16
C 278
S 313 AAPL 2846 14
C 38
S 314 AAPL 6469 3
B 315 AMZN 6761 8
S 316 GOOG 4572 15
C 67
S 317 AMZN 8155 13
S 318 AAPL 6950 10
S 319 AMZN 4299 5
S 320 AAPL 7257 15
C 185
B 321 AMZN 5730 17
B 322 GOOG 6801 1
C 165
B 323 AMZN 8973 20
S 324 AAPL 5636 13
C 57
S 325 GOOG 8353 13
C 261
S 326 AMZN 6907 5
S 327 GOOG 1483 5
B 328 AAPL 3930 19
C 137
B 329 AAPL 8844 16
S 330 AAPL 7523 5
S 331 AAPL 1483 10
C 221
C 52
B 332 AAPL 5932 2
C 91
S 333 AAPL 8675 7
B 334 GOOG 8566 12
S 335 AAPL 4753 18
B 336 AMZN 6243 19
S 337 AAPL 5941 12
S 338 AMZN 5586 13
C 259
B 339 GOOG 2805 8
C 67
C 78
S 340 GOOG 4022 3
C 265
S 341 GOOG 4250 19
C 285
C 208
S 342 AMZN 6123 3
B 343 GOOG 1946 14
B 344 AAPL 5950 16
S 345 AAPL 1945 5
S 346 AMZN 7749 4
C 92
C 133
S 347 AMZN 6473 4
B 348 AMZN 8063 19
S 349 AMZN 8362 17
S 350 AAPL 2606 15
C 345
S 351 AMZN 5813 19
B 352 AMZN 3693 6
B 353 AAPL 8598 14
B 354 AMZN 8882 3
C 262
S 355 AMZN 7044 1
S 356 GOOG 8078 9
C 251
S 357 GOOG 2788 3
C 176
B 358 AMZN 4930 6
B 359 AAPL 5130 6
B 360 AMZN 8758 5
B 361 GOOG 5594 7
B 362 GOOG 8785 7
S 363 AAPL 2166 19
B 364 AAPL 7507 4
C 177
S 365 GOOG 7641 7
S 366 AAPL 8228 18
C 239
S 367 GOOG 5355 8
B 368 AAPL 3200 19
C 55
S 369 AMZN 6223 10
C 38
C 327
B 370 AMZN 8534 13
B 371 GOOG 2490 5
C 237
S 372 AMZN 5678 12
B 373 AMZN 1398 11
S 374 GOOG 6991 7
S 375 AAPL 7650 12
S 376 AAPL 2982 12
C 57
C 250
C 135
S 377 AMZN 3358 5
S 378 AAPL 6782 9
C 360
S 379 AAPL 6530 8
