order-book/a1-a2-testcases/intermediate-random-2.in

    # Random doubly threaded test case
    
2
o
0 B 0 GOOG 4478 4
0 S 1 AAPL 6531 19
0 S 2 AMZN 5726 18
0 C 0
0 B 3 GOOG 7525 3
0 C 1
0 C 2
0 B 4 GOOG 2820 5
0 S 5 AMZN 6708 20
0 S 6 AMZN 2765 20
0 C 2
0 B 7 GOOG 8413 6
0 C 7
0 B 8 GOOG 7344 4
0 B 9 AMZN 6548 5
0 S 10 AMZN 1447 20
0 B 11 AMZN 8879 14
0 S 12 AMZN 1684 9
0 B 13 AMZN 4036 3
0 B 14 GOOG 6347 4
0 S 15 AAPL 2461 19
0 C 15
0 S 16 AMZN 3337 6
0 S 17 AMZN 4896 10
0 S 18 AAPL 2256 12
0 C 10
0 C 7
0 C 14
0 B 19 AAPL 1138 6
0 S 20 AMZN 6378 20
0 S 21 AMZN 8464 15
0 B 22 AMZN 1973 14
0 C 12
0 S 23 GOOG 6647 16
0 S 24 GOOG 5470 6
0 S 25 AMZN 8548 14
0 B 26 AAPL 7367 2
0 C 24
0 S 27 AAPL 4505 11
0 S 28 AAPL 4917 7
0 B 29 AMZN 3977 1
0 C 19
0 S 30 GOOG 3113 1
0 B 31 GOOG 4794 10
0 S 32 AAPL 6488 18
0 S 33 GOOG 6942 17
0 B 34 AMZN 5074 10
0 S 35 GOOG 7445 14
0 B 36 AMZN 6964 13
0 C 12
0 S 37 AMZN 1518 4
0 B 38 AMZN 6671 18
0 C 31
0 C 24
0 B 39 AAPL 5746 13
0 C 3
0 C 11
0 C 34
0 S 40 AAPL 8145 3
0 B 41 AMZN 7797 7
0 B 42 GOOG 2121 11
0 B 43 AAPL 8020 12
0 C 30
0 C 6
0 C 33
0 C 23
0 B 44 AAPL 6801 3
0 B 45 AAPL 6720 2
0 B 46 AMZN 6135 20
0 S 47 GOOG 7364 2
0 S 48 AAPL 3158 12
0 B 49 AAPL 6671 12
0 S 50 GOOG 1087 10
0 B 51 GOOG 4690 17
0 C 33
0 S 52 AMZN 7467 3
0 B 53 AMZN 5445 7
0 S 54 AMZN 8447 1
0 S 55 AMZN 2697 16
0 B 56 AMZN 7346 20
0 S 57 AMZN 5839 10
0 S 58 AAPL 4906 15
0 B 59 GOOG 8838 9
0 S 60 GOOG 1192 12
0 C 2
0 B 61 GOOG 7664 7
0 B 62 AAPL 1632 15
0 B 63 GOOG 4265 5
0 C 1
0 C 46
0 S 64 AAPL 4391 8
0 B 65 GOOG 6187 19
0 C 33
0 B 66 AAPL 3372 4
0 S 67 AMZN 1804 20
0 B 68 GOOG 4124 13
0 B 69 AAPL 5237 17
0 B 70 AAPL 6659 15
0 C 19
0 C 29
0 C 58
0 S 71 GOOG 5967 2
0 S 72 GOOG 8630 14
0 S 73 AAPL 8430 10
0 B 74 GOOG 6527 20
0 B 75 AMZN 5734 15
0 C 74
0 B 76 AMZN 5589 13
0 B 77 AMZN 8723 12
0 B 78 AAPL 5637 19
0 S 79 AMZN 5343 6
0 C 44
0 C 77
0 C 40
0 S 80 GOOG 3666 7
0 C 41
0 C 6
0 B 81 AMZN 7967 3
0 C 12
0 B 82 AMZN 1105 4
0 S 83 AAPL 4227 16
0 S 84 AMZN 2931 20
0 B 85 AMZN 4359 14
0 C 13
0 B 86 AMZN 7380 15
0 S 87 AAPL 8607 3
0 C 64
0 S 88 AAPL 5358 7
0 C 18
0 B 89 AMZN 2313 19
0 C 68
0 S 90 AAPL 3061 1
0 S 91 GOOG 5778 3
0 B 92 AAPL 7468 9
0 B 93 AMZN 1412 9
0 C 24
0 C 10
0 C 13
0 B 94 GOOG 4952 1
0 C 94
0 B 95 GOOG 7038 11
0 B 96 AAPL 8754 4
0 C 20
0 B 97 AMZN 6069 17
0 C 29
0 S 98 GOOG 6336 19
0 S 99 AMZN 5202 20
0 B 100 AMZN 7682 17
0 S 101 AMZN 2285 16
0 S 102 GOOG 7344 6
0 B 103 GOOG 7990 19
0 B 104 AAPL 3641 7
0 S 105 AAPL 3931 13
0 C 91
0 C 72
0 B 106 AAPL 1592 1
0 C 87
0 S 107 AAPL 5238 15
0 S 108 GOOG 6641 18
0 B 109 AAPL 2939 12
0 B 110 AMZN 1950 16
0 S 111 AAPL 1334 3
0 S 112 AMZN 1003 5
0 S 113 GOOG 3510 18
0 S 114 AMZN 5891 12
0 C 10
0 C 94
0 C 99
0 S 115 AAPL 3661 17
0 C 112
0 B 116 GOOG 4144 8
0 B 117 AMZN 6305 3
0 B 118 AAPL 2118 17
0 C 0
0 B 119 AAPL 8937 6
0 S 120 AAPL 7161 3
0 B 121 AMZN 2680 20
0 B 122 GOOG 3720 14
0 S 123 GOOG 6508 1
0 S 124 AMZN 2661 11
0 S 125 GOOG 5529 11
0 S 126 AMZN 5450 6
0 C 44
0 B 127 AMZN 8260 11
0 B 128 AAPL 3689 6
0 S 129 GOOG 5393 9
0 B 130 AMZN 2971 20
0 B 131 GOOG 1132 3
0 B 132 AMZN 2005 7
0 S 133 AMZN 3842 4
0 C 92
0 S 134 AAPL 7262 19
0 C 33
0 B 135 GOOG 4423 7
0 B 136 GOOG 6227 13
0 B 137 GOOG 3534 6
0 C 17
0 S 138 GOOG 1458 6
0 B 139 GOOG 7578 4
0 C 85
0 B 140 AMZN 4886 17
0 C 59
0 B 141 AMZN 2257 17
0 B 142 AMZN 5984 2
0 B 143 AMZN 2426 13
0 C 142
0 C 110
0 S 144 AMZN 6796 2
0 B 145 GOOG 7612 19
0 C 139
0 S 146 GOOG 1649 16
0 C 30
0 S 147 AAPL 5015 16
0 C 99
0 B 148 AMZN 2598 15
0 S 149 AMZN 7398 18
0 S 150 GOOG 4419 14
0 B 151 AAPL 1078 9
0 B 152 GOOG 5521 8
0 B 153 GOOG 7133 3
0 B 154 GOOG 7423 3
0 C 128
0 B 155 AMZN 2131 5
0 C 6
0 S 156 GOOG 5059 10
0 C 6
0 C 109
0 C 33
0 C 72
0 B 157 GOOG 3186 12
0 C 47
0 B 158 GOOG 2356 10
0 S 159 GOOG 7460 17
0 S 160 GOOG 2363 17
0 S 161 AAPL 1143 4
0 C 9
0 S 162 GOOG 4698 3
0 B 163 GOOG 6809 2
0 B 164 AAPL 2823 20
0 B 165 GOOG 3832 20
0 C 157
0 S 166 GOOG 4507 19
0 B 167 AMZN 1229 18
0 B 168 AMZN 8055 3
0 C 110
0 C 89
0 S 169 AAPL 3967 19
0 C 19
0 S 170 AAPL 5816 14
0 C 57
0 C 128
0 B 171 GOOG 7220 1
0 S 172 GOOG 1312 19
0 B 173 AAPL 6333 9
0 B 174 AAPL 6608 12
0 S 175 AAPL 5163 9
0 C 12
0 B 176 GOOG 3286 5
0 S 177 AMZN 1180 17
0 B 178 AMZN 3750 13
0 B 179 AMZN 1815 16
0 B 180 GOOG 8600 2
0 C 90
0 B 181 GOOG 5888 6
0 S 182 AAPL 4522 5
0 S 183 AMZN 4461 19
0 B 184 AMZN 5287 4
0 C 70
0 B 185 AAPL 1470 9
0 S 186 AAPL 3359 15
0 C 75
0 S 187 AAPL 4399 8
0 C 59
0 S 188 GOOG 1820 9
0 B 189 AAPL 7551 1
0 S 190 AAPL 1968 8
0 C 120
0 B 191 AMZN 2697 11
0 B 192 AMZN 8779 15
0 B 193 AAPL 5999 16
0 S 194 AMZN 4402 14
0 S 195 AMZN 4204 16
0 B 196 AAPL 7564 3
0 S 197 GOOG 3688 17
0 B 198 AMZN 7097 20
0 B 199 GOOG 3823 2
0 B 200 AMZN 2889 10
0 C 73
0 C 194
0 S 201 GOOG 3066 7
0 S 202 AAPL 3488 10
0 B 203 GOOG 1620 7
0 S 204 AMZN 7531 11
0 S 205 AAPL 8489 14
0 S 206 AMZN 1406 12
0 S 207 AAPL 3919 3
0 C 61
0 S 208 GOOG 5715 17
0 B 209 AMZN 2324 12
0 B 210 AMZN 7937 8
0 C 114
0 B 211 AMZN 8606 14
0 C 160
0 S 212 AAPL 8448 5
0 B 213 AAPL 2131 8
0 C 84
0 S 214 AMZN 1163 9
0 C 26
0 B 215 AMZN 6205 13
0 C 188
0 S 216 GOOG 3811 11
0 B 217 AAPL 3282 8
0 B 218 GOOG 8685 2
0 B 219 GOOG 3718 18
0 B 220 AMZN 3585 15
0 B 221 AMZN 6807 8
0 B 222 GOOG 2737 20
0 B 223 GOOG 8152 7
0 C 70
0 C 190
0 B 224 AAPL 1967 14
0 C 168
0 S 225 GOOG 4305 12
0 B 226 AAPL 8542 14
0 C 197
0 B 227 AMZN 5526 19
0 S 228 GOOG 8600 1
0 C 152
0 S 229 AMZN 1199 7
0 C 221
0 B 230 GOOG 1322 15
0 B 231 AMZN 1620 18
0 C 169
0 B 232 GOOG 8686 7
0 S 233 AAPL 2645 18
0 S 234 GOOG 7298 4
0 B 235 AMZN 3968 5
0 B 236 GOOG 2143 19
0 C 155
0 B 237 GOOG 5252 1
0 C 62
0 S 238 GOOG 3273 13
0 C 6
0 S 239 GOOG 4661 5
0 B 240 AAPL 6343 11
0 S 241 AAPL 6306 18
0 C 81
0 B 242 AMZN 4683 3
0 C 24
0 S 243 AAPL 1675 12
0 B 244 AMZN 6288 11
0 B 245 AAPL 3298 8
0 C 180
0 B 246 AMZN 1033 9
0 S 247 AMZN 7919 19
0 B 248 AAPL 6871 13
0 S 249 GOOG 2204 3
0 S 250 AAPL 1979 3
0 C 175
0 S 251 AAPL 8263 16
0 C 243
0 S 252 AMZN 2642 4
0 S 253 GOOG 2321 13
0 S 254 AAPL 8101 6
0 C 175
0 S 255 AAPL 4886 1
0 S 256 AAPL 3659 15
0 C 107
0 S 257 AMZN 6317 19
0 C 72
0 C 24
0 B 258 AMZN 2526 10
0 C 72
0 S 259 AAPL 8812 1
0 S 260 AMZN 5749 14
0 S 261 AAPL 3011 16
0 S 262 AMZN 5864 2
0 B 263 GOOG 2055 2
0 S 264 AMZN 1629 15
0 C 131
0 B 265 AAPL 3477 18
0 C 183
0 C 171
0 C 28
0 C 45
0 C 33
0 B 266 AAPL 4451 6
0 B 267 AAPL 1977 16
0 C 129
0 C 6
0 B 268 AAPL 1410 10
0 S 269 GOOG 8161 13
0 S 270 GOOG 1733 17
0 S 271 AAPL 2905 15
0 S 272 GOOG 7481 13
0 C 59
0 C 12
0 C 43
0 S 273 GOOG 3856 12
0 C 37
0 C 209
0 B 274 AMZN 7678 9
0 B 275 AAPL 5808 3
0 S 276 GOOG 7509 20
0 S 277 AAPL 8365 1
0 C 92
0 C 118
0 C 36
0 S 278 GOOG 8588 20
0 S 279 AMZN 6587 8
0 S 280 AAPL 1374 15
0 S 281 GOOG 5499 11
0 B 282 AMZN 8575 17
0 B 283 AMZN 6077 6
0 C 186
0 B 284 GOOG 1511 2
0 S 285 AAPL 5373 8
0 S 286 AMZN 4107 10
0 S 287 AAPL 6036 13
0 S 288 AMZN 5654 15
0 C 107
0 B 289 AAPL 5213 20
0 C 199
0 S 290 AMZN 6840 19
0 B 291 AAPL 4631 19
0 C 57
0 B 292 GOOG 4702 7
0 B 293 AAPL 6244 10
0 C 240
0 S 294 AMZN 1463 12
0 S 295 AMZN 4362 4
0 C 75
0 B 296 GOOG 2168 2
0 S 297 AMZN 4685 11
0 B 298 AAPL 8239 17
0 C 140
0 C 3
0 C 238
0 S 299 GOOG 4176 8
0 C 95
0 C 63
0 B 300 AMZN 4243 2
0 C 212
0 S 301 AMZN 5248 3
0 C 277
0 S 302 AMZN 5323 20
0 B 303 AAPL 5644 1
0 C 103
0 S 304 GOOG 4996 14
0 S 305 AMZN 3025 20
0 C 105
0 S 306 AAPL 8254 3
0 C 287
0 S 307 AAPL 8925 16
0 S 308 AMZN 2168 10
0 C 190
0 S 309 AMZN 7116 1
0 B 310 AAPL 2783 6
0 B 311 AMZN 7586 18
0 S 312 AAPL 7812 14
0 S 313 AMZN 3436 10
0 S 314 GOOG 6451 18
0 B 315 GOOG 5000 3
0 S 316 AAPL 8807 11
0 B 317 AAPL 6128 20
0 B 318 AAPL 4677 20
0 C 17
0 S 319 GOOG 7109 13
0 B 320 AAPL 6707 8
0 S 321 AMZN 3026 19
0 B 322 AAPL 6692 6
0 S 323 GOOG 7246 2
0 S 324 AAPL 2702 20
0 C 192
0 B 325 GOOG 4896 12
0 C 288
0 C 276
0 C 264
0 S 326 AAPL 4230 19
0 C 67
0 S 327 AAPL 5279 18
0 S 328 AAPL 7996 5
0 C 44
0 C 58
0 C 268
0 S 329 GOOG 7421 13
0 C 151
0 S 330 GOOG 8530 15
0 B 331 AMZN 2064 20
0 S 332 AAPL 2982 9
0 S 333 AMZN 6877 10
0 B 334 AAPL 7908 7
0 S 335 AMZN 5153 20
0 C 6
0 S 336 AAPL 2014 7
